Workbook

Sheet Artigos
A1: Artigo | B1: Base | C1: Duplicado | D1: Disponível | E1: Triagem | F1: Incluído
A2: A framework for synthetic image generation and augmentation for improving automatic sewer pipe defect detection | B2: Science | C2: não | D2: sim | E2: não | F2: não
A3: A Method to Establish a Synthetic Image Dataset of Stored-Product Insects for Insect Detection | B3: IEEE | C3: não | D3: sim | E3: não | F3: não
A4: ACM Multimedia 2024 Grand Challenge Report for Artificial Intelligence Generated Image Detection | B4: ACM | C4: não | D4: sim | E4: sim | F4: sim
A5: Addressing Diffusion Model Based Counter-Forensic Image Manipulation for Synthetic Image Detection | B5: ACM | C5: não | D5: sim | E5: sim | F5: sim
A6: Advancing AI-Generated Image Detection: Enhanced Accuracy through CNN and Vision Transformer Models with Explainable AI Insights | B6: IEEE | C6: não | D6: sim | E6: sim | F6: sim
A7: Advancing Glaucoma Detection: Synthetic Image Generation via Generative Adversarial Networks and Classification with Pretrained MobileNetV2 | B7: IEEE | C7: não | D7: sim | E7: não | F7: não
A8: AI-Generated Image Detection using a Cross-Attention Enhanced Dual-Stream Network | B8: IEEE | C8: não | D8: sim | E8: sim | F8: sim
A9: AI-Generated Image Detection Using Semantic Feature | B9: IEEE | C9: não | D9: sim | E9: sim | F9: sim
A10: Artifact feature purification for cross-domain detection of AI-generated images | B10: Science | C10: sim | D10: sim | E10: não | F10: não
A11: AI-Generated Image Detection With Wasserstein Distance Compression and Dynamic Aggregation | B11: IEEE | C11: não | D11: sim | E11: sim | F11: sim
A12: Bottlenose dolphin identification using synthetic image-based transfer learning | B12: Science | C12: não | D12: sim | E12: não | F12: não
... A75: Unsupervised Generated Image Editing Method Based on Multi-Scale Hierarchical Disentanglement | B75: IEEE | C75: não | D75: sim | E75: não | F75: não

Sheet Base
A1: Número | B1: Título | C1: Autores | D1: Ano | E1: Foco Principal do Estudo | F1: Algoritmos/Técnicas Utilizadas | G1: Datasets Utilizados | H1: Métricas de Desempenho | I1: Resultados de Desempenho | J1: Limitações Identificadas | K1: Desafios Abordados | L1: Ferramentas Promissoras | M1: Implicações Sociais/Éticas | N1: Principais Insights
A2: 1 | B2: ACM Multimedia 2024 Grand Challenge Report for Artificial Intelligence Generated Image Detection | C2: Song, Shien and Yang, Jie and Chen, Jin and Qi, Han and Xue, Yifei and Lao, Yizhen and Yu, Yi | D2: 2024 | E2: Detecção de imagens geradas por IA (AI-generated image detection) | F2: GAN, Stable Diffusion, Sora, Kling, Luma, Google Veo, Pika, Runway, LlamaGen, Transformer, CNN, Data augmentation (horizontal flipping, Gaussian noise, random cropping), Fully Convolutional Masked AutoEncoder | G2: N/A | H2: Acurácia(ACC), Precisão Média (AP), Velocidade de Detecção (FPS) | I2: Melhor AP = 0.9762, Melhor FPS = 112 (equipe wodezixingche); Score final = 0.9812 (equipe wodezixingche) | J2: Limitações Identificadas: N/A (o artigo é um relatório de desafio, não foca nas limitações de um estudo específico, mas sim nos desafios do campo) | K2: Melhorar a capacidade de generalização para identificar amostras desconhecidas e emergentes; Equilibrar precisão, versatilidade e eficiência computacional; Lidar com o desequilíbrio de dados gerados por algoritmos mais antigos vs. mais novos; Simular condições do mundo real onde as imagens sofrem transformações (redimensionamento, captura de imagem). | L2: Redes neurais avançadas, aumento robusto de dados, datasets diversos para equilibrar o potencial criativo da IA com a necessidade de manter a confiança na autenticidade da informação visual. | M2: Segurança, mídia digital, processos legais (onde a autenticidade é crítica), desinformação (implícito na necessidade de detecção de imagens geradas por IA). | N2: Detecção sob múltiplos geradores e ambientes realistas: O desafio proposto explora a detecção de imagens geradas por IA usando um conjunto diversificado de modelos (GANs, Diffusion, Sora, Kling, etc.) e simula condições reais (compressão, redimensionamento), promovendo soluções com alta generalização. Destaca-se a importância de métodos eficientes e escaláveis, com foco tanto em acurácia quanto em velocidade de inferência (FPS), refletindo a aplicabilidade prática da detecção em tempo real. | P2: ano | Q2: freq
A3: 2 | B3: Addressing Diffusion Model Based Counter-Forensic Image Manipulation for Synthetic Image Detection | C3: N Herur, Aryan and Santhosh, Vaibhav and Shetty, Nishanth and Seelamantula, Chandra Sekhar | D3: 2025 | E3: Abordar a manipulação de imagens contra-forense baseada em modelos de difusão para detecção de imagens sintéticas, especificamente a reconstrução de imagens reais com autoencoders de modelos de difusão para fazê-las parecerem sintéticas, e desenvolver algoritmos para detectar essas imagens manipuladas, além de imagens reais e puramente sintéticas. | F3: Convolutional Neural Networks (CNNs), Contrastive Language Image Pretraining (CLIP), Diffusion Models (DMs), Autoencoders de Diffusion Models (Stable Diffusion 1.4), Multilayer Perceptron (MLP), Discrete Cosine Transform (DCT), Ensemble Models. | G3: Elsa-D3, COCO, ImageNet, UCID. | H3: Acurácia (ACC), Precisão(P), Revocação (rec), F1-score, AUC (Área sob a Curva ROC). | I3: Acurácia de 99.2% na classificação multiclasse (Real vs. Manipulado vs. Fake) usando o modelo ensemble. O modelo ensemble supera o classificador CLIP multiclasse ao aumentar a precisão na detecção de imagens manipuladas e falsas.O modelo CLIP sozinho já apresentava alto desempenho para detecção de reais (recall de 100% em vários casos). | J3: Vulnerabilidade dos artefatos DCT ao redimensionamento de imagens, o que causa uma queda drástica no desempenho. A dependência do método proposto na presença de artefatos DCT em imagens reconstruídas por DM pode ser afetada se DMs futuros forem capazes de reconstruir imagens reais sem produzir esses artefatos. | K3: Melhorar a detecção de imagens sintéticas fora da distribuição (OoD) e a robustez a técnicas comuns de pré-processamento de imagem. Explorar a natureza de ataques contra-forenses intrincados (reconstrução de imagens reais com autoencoders de modelos de difusão). Classificar imagens manipuladas como uma classe separada para fornecer informações forenses críticas. | L3: Técnicas de pré-processamento apropriadas para detecção de imagens sintéticas, detecção de ataques contra-forenses, e experimentos usando técnicas de classificação modernas com a ajuda de Vision Language Models (VLMs) como Vision Image Transformers. | M3: Desinformação e ataques contra-forenses maliciosos, onde a manipulação intencional de imagens reais pode enganar algoritmos de detecção e minar a confiança nos modelos existentes. | N3: Vulnerabilidade dos detectores baseados em artefatos de frequência: A reconstrução de imagens reais por autoencoders de DMs introduz artefatos de frequência que são indistinguíveis dos artefatos típicos de imagens sintéticas, levando detectores tradicionais a classificarem imagens reais manipuladas como falsas. Isso evidencia uma fragilidade crítica nas abordagens atuais que dependem exclusivamente de traços espectrais. Importância de abordagens multi-features: O uso combinado de características extraídas do domínio da frequência (DCT) e de representações semânticas avançadas (CLIP) permite diferenciar efetivamente imagens reais, manipuladas e sintéticas. A complementaridade dessas informações melhora a robustez e a confiabilidade da detecção. Eficiência do ensemble para detecção multiclasses: O método em ensemble proposto atua inicialmente filtrando imagens reais via CLIP e, em seguida, refinando a distinção entre manipuladas e falsas por meio do classificador DCT. Essa estratégia hierárquica maximiza a precisão e reduz falsos positivos e negativos, especialmente para imagens manipuladas. Dataset diversificado e realista: A utilização de datasets variados — Elsa-D3, COCO, ImageNet e UCID — para treinamento e testes, incluindo múltiplos modelos de difusão populares (Stable Diffusion em várias versões, Deep Floyd), confere maior generalização e validade prática aos resultados obtidos. Resiliência e limitações técnicas: O desempenho dos classificadores baseados em DCT cai drasticamente quando as imagens são redimensionadas, evidenciando a necessidade de técnicas de pré-processamento robustas para uso em cenários reais, onde manipulações básicas são comuns. Panorama futuro promissor: A pesquisa sugere que a incorporação de Vision Language Models (VLMs) e transformadores de imagem pode abrir caminho para detectores mais poderosos e resistentes a contra-forenses, superando limitações dos métodos atuais. Relevância forense da classificação tripartida: Identificar não apenas imagens falsas, mas também aquelas reais que foram manipuladas por DMs, é crucial para aplicações forenses, pois preserva informações sobre interferências intencionais, melhorando a transparência e a confiabilidade do processo de verificação. | P3: 2022 | Q3: =COUNTIF($D$2:$D$45,P3) -> 1
A4: 3 | B4: Advancing AI-Generated Image Detection: Enhanced Accuracy through CNN and Vision Transformer Models with Explainable AI Insights | C4: Hossain, Md. Zahid and Uz Zaman, Farhad and Islam, Md. Rakibul | D4: 2023 | E4: Detecção de imagens geradas por IA, explorando as capacidades de modelos CNN e Vision Transformer, e utilizando Explainable AI (Grad-CAM) para interpretar as decisões do modelo. | F4: Convolutional Neural Networks (CNNs), Vision Transformer (ViT-S16), Generative Adversarial Networks (GANs), Latent Diffusion Models (LDMs), Grad-CAM (Gradient-weighted Class Activation Mapping), Adam optimizer, ReLU activation function. | G4: CIFAKE: Real and AI-Generated Synthetic Images, ImageNet-21k, ImageNet-1k. | H4: Acurácia (ACC), Precisão(P), Revocação (rec), F1-Score. | I4: O modelo CNN selecionado alcançou uma acurácia de 96.31%, 96.13% de precisão e 96.50% de recall. O ViT-S16 pré-treinado teve a menor acurácia (87.09%), precisão (85.98%) e recall (88.63%). | J4: O desempenho do modelo Vision Transformer foi subótimo, possivelmente devido à resolução limitada das imagens (32x32 pixels). A generalização para novos datasets e imagens de alta resolução é uma limitação. | K4: A crescente dificuldade em distinguir imagens geradas por IA de imagens reais devido ao realismo. A manipulação e disseminação de desinformação através de imagens geradas por IA. A necessidade de técnicas auxiliadas por computador para identificar essas imagens. | L4: Extender o teste dos modelos para diversos datasets, especialmente aqueles com imagens de alta resolução. Explorar imagens geradas por diferentes GANs para entender a robustez dos modelos em várias estruturas generativas. | M4: Preocupações sociais crescentes relacionadas à disseminação de imagens sintéticas para fins enganosos e propagandísticos. A importância de combater notícias falsas e garantir a segurança cibernética. | N4: Comparação entre arquiteturas e interpretabilidade: O estudo revela que modelos CNN ainda superam Transformers como o ViT em imagens de baixa resolução, destacando que a escolha da arquitetura deve considerar o contexto do dataset. Além disso, o uso de Explainable AI (Grad-CAM) traz transparência ao processo decisório, uma necessidade crescente em aplicações críticas como jornalismo e segurança. | P4: 2023 | Q4: =COUNTIF($D$2:$D$45,P4) -> 11
A5: 4 | B5: AI-Generated Image Detection using a Cross-Attention Enhanced Dual-Stream Network | C5: Xi, Ziyi and Huang, Wenmin and Wei, Kangkang and Luo, Weiqi and Zheng, Peijia | D5: 2023 | E5: Detecção de imagens geradas por IA (AIGC), especificamente imagens de texto para imagem (T2I), utilizando uma rede de fluxo duplo aprimorada por atenção cruzada para capturar anomalias inerentes e distinguir T2I de fotografias (PG). | F5: Dual-stream network (residual stream e content stream), Cross Multi-Head Attention Mechanism, Spatial Rich Model (SRM), CNN modules, Fully Connected Layer, Adam optimizer, ReLU activation function, Cross Entropy Loss, ResNet18, VAE, GAN, Diffusion Models (Stable Diffusion, Disco Diffusion, MidJourney, DALL·E2). | G5: DALL·E2, DreamStudio (datasets criados pelos autores), ALASKA, SPL2018, DsTok | H5: Taxa de Verdadeiros Positivos (TPR), Taxa de Verdadeiros Negativos (TNR), Acurácia (ACC). | I5: O método proposto supera consistentemente as técnicas tradicionais de detecção de CG e outros métodos comparáveis, especialmente em resoluções de imagem mais altas (ex: >98.5% de acurácia em 256x256). Mantém um desempenho impressionante mesmo em resoluções mais baixas (ex: 93.1% e 97.8% de acurácia para DALL·E2 e DreamStudio em 64x64). Demonstra robustez contra várias operações de pós-processamento, como cromaticidade, brilho, contraste, nitidez, rotação e desfoque. | J5: N/A (o artigo foca nos avanços e eficácia do método proposto, não explicitando limitações). | K5: A crescente sofisticação das imagens geradas por IA, tornando-as indistinguíveis de imagens reais. A inadequação dos métodos convencionais de detecção de CG para identificar imagens geradas por AIGC devido às disparidades entre CG e AIGC. A necessidade de uma análise abrangente das anomalias inerentes produzidas por AIGC. | L5: A rede de fluxo duplo aprimorada por atenção cruzada para detecção de T2I. A exploração de outros tipos de falsificações geradas por IA. Aprimoramento contínuo da abordagem de rede de fluxo duplo. | M5: A natureza enganosa das imagens forjadas produzidas por AIGC e a necessidade de menos intervenção humana, o que as torna mais perigosas. A importância de distinguir T2I de fotografias para combater a desinformação. | N5: Cross-Attention é Eficaz para T2I com Modelos de Difusão Focado em imagens geradas por texto (ex: DALL·E2, DreamStudio), o modelo dual-stream com atenção cruzada superou abordagens clássicas em todos os benchmarks, com acurácia de até 98.5%. A inovação está em capturar artefatos de baixa e alta frequência simultaneamente. Contudo, o artigo não discute limitações práticas, como adversarial robustness ou interpretabilidade. | P5: 2024 | Q5: =COUNTIF($D$2:$D$45,P5) -> 22
A6: 5 | B6: AI-Generated Image Detection Using Semantic Feature | C6: Chen, Hau-Ching and Shen, Yu-Pin and Yeh, Yi-Hung and Chen, Jiann-Liang | D6: 2025 | E6: O artigo investiga a eficácia do modelo CLIP Vision Transformer (ViT) na detecção de imagens geradas por IA, com foco na capacidade de generalização baseada em características semânticas, em oposição à detecção de padrões específicos de datasets. O trabalho propõe uma abordagem de validação cruzada em que o modelo é treinado em imagens geradas por um modelo específico e testado em imagens provenientes de outros geradores, com o objetivo de simular cenários reais onde o detector encontra imagens sintéticas nunca vistas. A principal hipótese é que, ao extrair significados semânticos em vez de artefatos de baixo nível, o CLIP ViT consegue detectar falsificações com maior robustez e generalização. | F6: CLIP ViT (Vision Transformer), resnet50, Swin-T, DeiT-S, CNNSpot, Spec, F3Net, GramNet, Fully Connected Layer, Sigmoid Activation, Binary Classification, Cross-Validation, Transfer Learning, ImageNet-1k, MidJourney, Stable Diffusion V1.4, Stable Diffusion V1.5, ADM, GLIDE, Wukong, VQDM, BigGAN | G6: GenImage (composto por imagens reais do ImageNet-1k e imagens sintéticas geradas por MidJourney, Stable Diffusion V1.4, Stable Diffusion V1.5, ADM, GLIDE, Wukong, VQDM, BigGAN). | H6: Acurácia (ACC), Acurácia Média Cruzada (Cross-Validation Accuracy) | I6: O modelo CLIP ViT obteve desempenho superior na maioria dos cenários de validação cruzada, com acurácia média de 72.9%, superando outros detectores como ResNet-50 (66.9%), Swin-T (70.3%), DeiT-S (67.6%) e detectores baseados em características de frequência como CNNSpot, Spec, F3Net e GramNet. O CLIP ViT demonstrou maior generalização em imagens geradas por modelos não vistos durante o treinamento, comportamento oposto ao ResNet-50, que obteve desempenho significativamente inferior em datasets distintos do treinamento. Por exemplo, ao ser treinado com imagens do modelo ADM, o CLIP ViT obteve 87.8% de acurácia ao testar em imagens do GLIDE, enquanto o ResNet-50 atingiu apenas 56.0%. Além disso, o CLIP ViT mostrou desempenho estável mesmo diante da diversidade semântica e estrutural dos geradores testados. | J6: O modelo apresentou desempenho inferior ao lidar com imagens geradas por variantes de Stable Diffusion (V1.4, V1.5, Wukong), indicando que geradores da mesma arquitetura podem confundir os padrões semânticos captados pelo CLIP ViT. Os autores reconhecem que o estudo não fornece evidência direta da extração de características semânticas (como mapas de atenção ou visualizações de tokens), sendo essa uma limitação para a comprovação empírica da hipótese. Além disso, o modelo foi treinado por apenas uma época (epoch), o que pode ter restringido o desempenho total. | K6: A principal dificuldade abordada é a falta de generalização dos modelos tradicionais de detecção de imagens falsas, que tendem a identificar artefatos específicos de um dataset ou gerador. Em um cenário onde novos modelos de geração de imagens surgem continuamente, a capacidade de detectar imagens sintéticas sem depender de padrões conhecidos é essencial. Outro desafio citado é o baixo desempenho humano na detecção de imagens falsas (em média 60%), exigindo soluções computacionais mais robustas. | L6: CLIP ViT, Detecção baseada em características semânticas, Validação cruzada entre datasets de diferentes geradores, GenImage dataset, Uso de modelos pré-treinados com ajuste fino (fine-tuning), Abordagem supervisionada com arquitetura Transformer. | M6: O artigo menciona os riscos sociais e éticos do uso malicioso de imagens geradas por IA, como fraudes digitais, deepfakes envolvendo figuras públicas e proliferação de desinformação. O cenário apresentado na introdução destaca casos ocorridos em Taiwan, reforçando a urgência de ferramentas automatizadas confiáveis para mitigar os danos sociais e restaurar a confiança no conteúdo digital. | N6: A principal contribuição do artigo é demonstrar que modelos baseados em extração semântica, como o CLIP ViT, oferecem uma solução mais generalizável para a detecção de imagens falsas em comparação com abordagens tradicionais baseadas em CNNs ou padrões de frequência. O uso de validação cruzada entre oito modelos geradores diferentes revelou que o CLIP ViT não apenas obtém alta acurácia, mas também mantém desempenho estável em cenários adversos, o que indica que sua representação semântica transcende artefatos específicos. Embora ainda seja necessário investigar empiricamente como essas representações são formadas, o artigo aponta para um novo paradigma na detecção de imagens geradas por IA, em que a compreensão semântica pode ser a chave para combater manipulações visuais em escala global e dinâmica. | P6: 2025 | Q6: =COUNTIF($D$2:$D$45,P6) -> 10
A7: 6 | B7: AI-Generated Image Detection With Wasserstein Distance Compression and Dynamic Aggregation | C7: Lyu, Zihang and Xiao, Jun and Zhang, Cong and Lam, Kin-Man | D7: 2024 | E7: O artigo investiga a eficácia do modelo CLIP Vision Transformer (ViT) na detecção de imagens geradas por IA, com foco na capacidade de generalização baseada em características semânticas, em oposição à detecção de padrões específicos de datasets. O trabalho propõe uma abordagem de validação cruzada em que o modelo é treinado em imagens geradas por um modelo específico e testado em imagens provenientes de outros geradores, com o objetivo de simular cenários reais onde o detector encontra imagens sintéticas nunca vistas. A principal hipótese é que, ao extrair significados semânticos em vez de artefatos de baixo nível, o CLIP ViT consegue detectar falsificações com maior robustez e generalização.públic | F7: Dynamic Aggregation Classifier, Wasserstein Distance Compression, Wasserstein Clustering, CLIP:ViT , Linear Kernel, Rank-One Matrix Regularization, Adam Optimizer, Early Stopping, Função de Perda Cross-Entropy, Feature Space Aggregation, Optimal Transport Mapping, Variational Method, Sigmoid Function, Batch Size 256. ProGAN, CycleGAN, BigGAN, StyleGAN, GauGAN, StarGAN, Deepfakes, SITD (Seeing in the Dark), SAN (Second-order Attention Network), CRN (Cascaded Refinement Networks), IMLE (Implicit Maximum Likelihood Estimation), Guided Diffusion Model, Latent Diffusion Models (LDM) , Glide, DALL-E. CNN Classifier, Patch Classifier, Co-occurrence Matrices + Deep Learning , Spec, UnivFD, UnivFD. Autoencoder, Markov Random Fields, GANs, Diffusion Models, Image-to-Image Translation, Style Transfer, Low-Light Enhancement, Super-Resolution, Feature Binarization, Metric Space Geometry Preservation. | G7: UnivFD (UniversalFakeDetection), ForenSynths, LSUN, ProGAN, CycleGAN, BigGAN, StyleGAN, GauGAN, StarGAN, Deepfakes, SITD, SAN, CRN, IMLE, Guided Diffusion Model, LDM, Glide, DALL-E. | H7: Acurácia (ACC), AUC (Área sob a Curva ROC),Curva ROC,AUC Média em Generalização de Domínio Aberto | I7: O método proposto alcançou acurácia de 99.1% em dados vistos e até 91.4% de AUC médio em dados de domínio aberto, superando diversos métodos de última geração como Gram-Net, F3Net, CNN-Spot, Fusing, DIRE-G, UnivFD e outros. A compressão baseada na distância de Wasserstein mostrou-se eficaz para preservar os componentes discriminativos da distribuição de features, permitindo melhor generalização para domínios não vistos. O classificador com agregação dinâmica foi capaz de aprender representações mais robustas de diferentes fontes de dados e adaptar seu julgamento com base na distribuição global das amostras, diferentemente de classificadores lineares fixos. | J7: Embora os resultados sejam promissores, os autores reconhecem que o desempenho ainda pode variar dependendo da escolha dos clusters e das características extraídas, especialmente quando o espaço latente apresenta sobreposição entre domínios reais e sintéticos. O modelo depende da qualidade das features extraídas previamente (CLIP ViT) e não realiza aprendizado de representação de forma fim-a-fim. Outro ponto é a sensibilidade à parametrização da compressão de Wasserstein e ao número de componentes dinâmicos utilizados. | K7: A falta de generalização de detectores de imagens geradas por IA para modelos desconhecidos, o viés gerado por treinamento restrito a modelos específicos de GAN ou diffusion, e a incapacidade de classificadores tradicionais lidarem com a diversidade de distribuições geradas por modelos modernos. O trabalho enfrenta o desafio de como representar e classificar amostras com base em informações de distribuição global e não apenas características pontuais. | L7: Uso de compressão de distância de Wasserstein para representar diferenças de distribuição, agregação dinâmica baseada em componentes latentes, clustering no espaço de Wasserstein, extração de features com CLIP ViT, ajuste com Kernel Linear com componentes estáticos e dinâmicos, regularização de matriz de rank um para controlar sobreajuste, arquitetura modular que separa extração de features e aprendizado de decisão. | M7: O artigo aborda o uso indevido crescente de imagens geradas por IA, especialmente em deepfakes, desinformação, falsificações visuais e segurança digital. A detecção eficaz de tais imagens é fundamental para garantir confiança em plataformas digitais e ferramentas forenses, exigindo soluções que possam se adaptar a modelos geradores em rápida evolução. Detectores robustos e generalizáveis são vitais para combater ameaças sociais e éticas emergentes. | N7: O trabalho propõe uma nova abordagem centrada em representações de distribuição via distância de Wasserstein e classificação por agregação dinâmica, que se mostrou superior aos detectores tradicionais, especialmente em domínios desconhecidos. Ao utilizar a estrutura de distribuição das features e realizar compressão inteligente dos componentes mais discriminativos, o modelo é capaz de preservar informação semântica essencial para a detecção de imagens geradas por IA, mesmo quando enfrentando modelos desconhecidos como diffusion models. O classificador dinâmico melhora a robustez e adaptabilidade, tornando esta proposta uma contribuição importante para o avanço dos sistemas de detecção forense de imagens sintéticas em escala real.
A8: 7 | B8: Artifact: A Large-Scale Dataset With Artificial And Factual Images For Generalizable And Robust Synthetic Image Detection | C8: Rahman, Md Awsafur and Paul, Bishmoy and Sarker, Najibul Haque and Hakim, Zaber Ibn Abdul and Fattah, Shaikh Anowarul | D8: 2023 | E8: Apresentar o ArtiFact, um dataset em larga escala com imagens artificiais e factuais para detecção generalizável e robusta de imagens sintéticas, e propor um esquema de classificação multi-classe combinado com uma estratégia de redução de stride de filtro para detectar imagens sintéticas de geradores vistos e não vistos. | F8: Deep CNN models, ConvNeXt-Large (backbone), Adam optimizer, Exponentially Decay scheduler, Categorical Cross Entropy loss with label smoothing, KFold, GroupKFold, GANs, Diffusion Models. | G8: ArtiFact (dataset proposto, contendo imagens de 8 fontes reais e 25 métodos de geração sintética, incluindo 13 GANs, 7 Diffusion e 5 outros), COCO (para legendas e máscaras de imagem). | H8: Acurácia (ACC) Acurácia Balanceada (BA). | I8: O método proposto supera consistentemente outras equipes de ponta no desafio IEEE VIP Cup 2022, com melhorias de 8.34% no Teste 1, 1.26% no Teste 2 e 15.08% no Teste 3. A abordagem multi-classe com FSR e classe UF alcançou a maior acurácia de 87.62%, superando o método binário tradicional em 9.41%. | J8: O problema fundamental da generalização persiste, pois mesmo os detectores de ponta encontram dificuldade ao enfrentar geradores nunca vistos durante o treinamento. A prevalência de deterioração de imagem em imagens de mídia social compactadas e redimensionadas, que são particularmente vulneráveis a atividades fraudulentas relacionadas a imagens sintéticas. A falta de um dataset de benchmark adequado, pois os datasets existentes são limitados pela falta de diversidade entre as fontes do gerador e as categorias de objetos. | K8: Prevenir atividades ilegais e prejudiciais relacionadas à geração de imagens falsas. A necessidade de um detector robusto e generalizável que seja capaz de generalizar para geradores vistos e não vistos, com ou sem deterioração, e que não perca informações críticas preservando traços do gerador na presença de deterioração. A perda de informações críticas causada por deteriorações de plataformas sociais. | L8: O dataset ArtiFact para avaliação de detectores de imagens sintéticas. O esquema de classificação multi-classe com uma classe dedicada para geradores não vistos. A redução de stride de filtro no bloco stem do backbone ConvNeXt para combater a perda de informações críticas. | M8: Ameaças à privacidade, autenticidade e segurança devido à geração de imagens sintéticas. A importância de detectar imagens falsas para prevenir atividades ilegais. | N8: Diversidade e Escala do Dataset ArtiFact: O ArtiFact é o maior conjunto de dados do tipo, contendo quase 2,5 milhões de imagens divididas em 964.989 reais e 1.531.749 falsas, abrangendo 25 métodos geradores, incluindo GANs, modelos de difusão e outros. Essa diversidade é crucial para treinar detectores capazes de generalizar melhor, pois cobre um amplo espectro de técnicas e categorias de objetos, refletindo a variedade encontrada em cenários do mundo real. Generalização com a Classe “Unseen Fake”: A inclusão de uma classe específica para imagens falsas geradas por geradores não vistos (Unseen Fake - UF) durante o treinamento é uma inovação essencial. Esse esquema multiclasse permite que o modelo aprenda características mais gerais e não dependa exclusivamente das assinaturas dos geradores conhecidos, ampliando a capacidade de detecção para casos inéditos, algo ausente em abordagens binárias tradicionais. Robustez a Degradações por Meio da FSR: As imagens compartilhadas em plataformas sociais frequentemente sofrem compressão e redimensionamento, que apagam detalhes técnicos essenciais para a detecção de imagens sintéticas. A técnica Filter Stride Reduction, aplicada na camada inicial da rede ConvNeXt, reduz a perda de informações importantes ao processar essas imagens, preservando os artefatos gerados pelo modelo sintético e aumentando a robustez do detector. Superioridade Comprovada em Competição Internacional: O método proposto atingiu resultados expressivos no IEEE VIP Cup 2022, superando as equipes concorrentes em até 15% de acurácia em conjuntos de teste com geradores desconhecidos e imagens degradadas. Isso valida na prática a eficácia da combinação do dataset com a abordagem multiclasse e a técnica FSR. Transformação do Problema Binário em Multiclasse: Tradicionalmente, a detecção de imagens falsas é tratada como um problema binário (real vs falso). Este trabalho demonstra que transformar a tarefa em multiclasse, onde cada gerador conhecido é uma classe distinta e há uma classe extra para geradores desconhecidos, melhora a capacidade do modelo de aprender diferentes características e padrões, o que reforça a generalização e a precisão. Importância dos Artefatos Únicos dos Modelos Generativos: Diferentes geradores deixam “impressões digitais” específicas nas imagens, como padrões em bandas de cor, espectros na frequência e variações na intensidade. Explorar essas características permite identificar a procedência das imagens sintéticas. No entanto, esses artefatos podem ser atenuados por compressão e manipulação, exigindo técnicas robustas como as propostas. Realismo na Construção do Dataset: Para simular condições reais, o ArtiFact aplica operações de recorte aleatório e compressão JPEG em imagens reais e sintéticas, reproduzindo as condições encontradas nas redes sociais. Essa estratégia assegura que os detectores treinados no dataset sejam mais eficazes em cenários do dia a dia, onde as imagens raramente estão em qualidade original.
A9: 8 | B9: Artifact feature purification for cross-domain detection of AI-generated images | C9: Zheling Meng and Bo Peng and Jing Dong and Tieniu Tan and Haonan Cheng | D9: 2024 | E9: Melhorar o desempenho da detecção de imagens geradas por IA em cenários de domínio cruzado (cross-generator e cross-scene) através da purificação de características de artefatos. | F9: Artifact Purification Network (APN) com purificação explícita (método de proposta de banda de frequência suspeita e decomposição de características espaciais) e purificação implícita (estratégia de treinamento baseada na estimação de informação mútua). Backbones: Swin-Transformer-tiny (ramo espacial) e resnet18 (ramo de frequência). Outros métodos de detecção de linha de base: Spec, CNNSpot, F3Net, GramNet, PatchFron, Swin-T, Patch5M, SIA, LNP, LGrad, UniversalDet. | G9: GenImage (ImageNet scene) e DiffusionForensics (DF) (LSUN-Bedroom scene) | H9: Acurácia (ACC) (%). | I9: Para detecção cross-generator, a acurácia média do APN é 5.6% a 16.4% maior que os 11 métodos anteriores no dataset GenImage, e 1.7% a 50.1% maior no dataset DiffusionForensics. Para detecção cross-scene, a acurácia média do APN em amostras fora do cenário é apenas 0.1% menor do que em amostras dentro do cenário. APN atinge 80.4% de acurácia média no GenImage e 98.7% no DF. | J9: Métodos existentes sofrem quedas de desempenho significativas em geradores e cenas fora do domínio. A purificação explícita não garante a purificação completa da informação de artefato diluída nas características. | K9: Superar a queda de desempenho de detectores de imagens geradas por IA em cenários cross-domain (cross-generator e cross-scene). Extrair características de artefatos agnósticas ao domínio. Lidar com o overfitting a artefatos específicos do gerador e a artefatos enviesados por objetos. | L9: Purificação explícita e implícita de características de artefatos. Combinação de modalidades (frequência e espacial). Uso de Visual Transformers e ResNets como backbones. Otimização do número de propostas para diferentes datasets. Possibilidade de usar meta-learning ou proposal dropout para determinar o número ideal de propostas. | M9: O rápido desenvolvimento de tecnologias de geração de conteúdo visual (AIGC) traz riscos potenciais de segurança, como a geração maliciosa de notícias falsas e biometria de pessoas sem permissão. A necessidade de pesquisas em detecção de imagens geradas por IA para mitigar esses riscos. | N9: Com o objetivo de aprimorar a detecção de imagens geradas por IA em cenários de domínio cruzado, este trabalho introduz a Artifact Purification Network (APN), uma arquitetura composta por dois ramos especializados: um baseado em Swin-Transformer para captar características espaciais e outro baseado em ResNet-18 para o domínio de frequência. A proposta se destaca por combinar uma purificação explícita — via extração seletiva de bandas de frequência suspeitas e decomposição de características espaciais — com uma purificação implícita baseada em estimação de informação mútua durante o treinamento. Avaliada nos datasets GenImage e DiffusionForensics, a APN obteve acurácia média entre 5.6% e 16.4% superior a 11 métodos comparados em detecção entre geradores distintos, e até 50.1% superior em domínios de cena distintos. Uma das principais contribuições do artigo é demonstrar que a purificação de artefatos pode isolar sinais universais de manipulação, tornando o detector mais robusto em contextos onde o gerador ou a cena não foram vistos previamente. Os autores sugerem, como continuidade, o uso de meta-learning e técnicas de proposal dropout para otimizar ainda mais a rede. O trabalho reforça a importância de desenvolver ferramentas generalizáveis e explicáveis frente ao avanço de tecnologias generativas que apresentam riscos reais à integridade da informação digital e à privacidade individual.
A10: 9 | B10: Computer-Generated Image Detection Based on Multi-Scale Feature Fusion Attention Module | C10: Xue, Yijie and Ji, Lixin and Li, Shaomei | D10: 2024 | E10: O artigo propõe um modelo de detecção de imagens geradas por computador que combina aprendizado de características em múltiplas escalas com o uso do Convolutional Block Attention Module (CBAM). A motivação central é lidar com o desafio de distinguir imagens sintéticas (CG) altamente realistas de imagens fotográficas (PG), especialmente diante da sofisticação crescente dos geradores e da semelhança visual entre ambas. O modelo visa extrair tanto características de baixo nível (detalhes e texturas) quanto características de alto nível (semântica e contexto global), e utiliza mecanismos de atenção para dar pesos diferenciados a partes relevantes da imagem. O artigo também aborda como a fusão multi-escalar e a atenção espacial e de canais ajudam a melhorar a capacidade discriminativa do modelo, sem adicionar grande custo computacional. | F10: VGG19 (pré-treinado), Multi-Scale Feature Fusion, CBAM (Convolutional Block Attention Module), Transfer Learning, Texture Enhancement Module, Convolutional Neural Networks (CNN), Adam Optimizer, Data Augmentation (crop, flip), Batch Normalization, Non-linear Activation, Fully Connected Layers. | G10: NLPR-LSCGB, Columbia Dataset. | H10: Acurácia (ACC) Taxa de Verdadeiros Positivos (TPR), Taxa de Verdadeiros Negativos (TNR), FPR (Taxa de Falsos Positivos), FNR (Taxa de Falsos Negativos) | I10: O modelo proposto atingiu 93.52% de acurácia no dataset NLPR-LSCGB e 98.86% no dataset Columbia, superando os métodos comparados, como Nguyen (89.64% e 94.45%), Quan (83.40% e 91.32%), Yao (83.40% e 88.92%) e Meena (91.00% e 93.85%). O desempenho elevado mostra a efetividade da fusão multi-escalar combinada com a atenção em destacar características relevantes para diferenciar imagens CG e PG, mesmo em bases desafiadoras como a NLPR-LSCGB, que possui imagens sintéticas e reais com estatísticas de cor, brilho e saturação muito próximas. | J10: Os autores reconhecem que embora a fusão multi-escalar de características e o uso de atenção melhorem a representação, a diferença semântica entre mapas de características de diferentes escalas ainda pode impactar negativamente a acurácia. Além disso, o artigo não menciona avaliação em cenários de generalização para modelos ou domínios não vistos, o que limita a análise da robustez do método em contextos adversos e reais. A dependência de redes base como VGG19 também pode limitar a escalabilidade ou a adaptação a arquiteturas mais modernas. | K10: O desafio principal abordado é o da detecção precisa de imagens sintéticas realistas, que se tornam cada vez mais indistinguíveis visualmente. O modelo busca superar os limites de abordagens que utilizam apenas características de um único nível ou técnicas manuais, que falham diante da complexidade visual crescente das imagens CG. Também é enfrentado o desafio de como destacar automaticamente as partes mais relevantes da imagem para a tarefa de detecção, sem sobrecarregar o modelo. | L10: Multi-Scale Feature Fusion, CBAM (atenção de canal e espacial), VGG19 com Fine-Tuning, Extração de Características de Baixo e Alto Nível, Módulo de Aprimoramento de Textura, Aplicações de Transfer Learning, Estratégias de Data Augmentation (corte, espelhamento), Treinamento com Otimização Adam, Arquitetura Modular (extração → aprimoramento → atenção → classificação). | M10: O artigo reconhece que imagens geradas por computador, apesar de populares em filmes, jogos e publicidade, também têm potencial de uso malicioso, como difamação, desinformação e disseminação de fake news. A detecção precisa é fundamental para preservar a integridade informacional em redes sociais e evitar que imagens sintéticas enganem o público ou causem pânico. A crescente acessibilidade de ferramentas de síntese amplia esses riscos, tornando urgente o desenvolvimento de sistemas forenses eficazes. | N10: A principal contribuição do artigo é o desenvolvimento de um modelo eficaz de detecção de imagens CG que combina informações em múltiplas escalas com atenção adaptativa, o que resulta em maior capacidade discriminativa e melhor desempenho do que métodos anteriores. O uso de mecanismos de atenção permite que o modelo focalize regiões cruciais e características relevantes da imagem, enquanto a fusão de diferentes níveis de representação proporciona uma compreensão mais rica e contextualizada da imagem analisada. O modelo mostrou excelente desempenho nos dois datasets utilizados, validando sua aplicação em contextos forenses digitais. A arquitetura proposta representa um avanço no uso eficiente de atenção e fusão de características para detecção de imagens sintéticas altamente realistas.
A11: 10 | B11: DC-BiNet: Towards interpretable generated image detection with dark channel prior | C11: Dengtai Tan and Chengyu Niu and Yang Yang and Deyi Yang and Boao Tan | D11: 2025 | E11: Detecção interpretável de imagens geradas por IA, com foco em superar as limitações de generalização e interpretabilidade dos métodos existentes, utilizando o prior de canal escuro. | F11: DC-BiNet (rede neural bilinear baseada em prior de canal escuro), 1x1 Convoluções, Group Normalization, ReLU, Bilinear Pooling, EfficientNet-B0 (backbone), AdamW optimizer, Mixed Precision Training, SHAP (SHapley Additive exPlanations) para análise de importância de características. | G11: ForenSynths (para treinamento e teste, incluindo 17 modelos GAN como ProGAN, StyleGAN, StyleGAN2, BigGAN, CycleGAN, StarGAN, GauGAN, Deepfake, AttGAN, BEGAN, CramerGAN, InfoMaxGAN, MMDGAN, RelGAN, S3GAN, SNGAN, STGAN), DiFF (para avaliação de modelos de difusão, incluindo 13 métodos de difusão como Midjourney, Stable Diffusion XL, FreeDoM_T, HPS, LoRA, DreamBooth, SDXL Refiner, FreeDoM_I, DiffFace, DCFace, Imagic, CoDiff, CycleDiff), LSUN, ImageNet, CelebA, CelebA-HQ, COCO, FaceForensics++, CelebA-Dialog. | H11: Acurácia (Acc), Precisão Média (AP), Revocação (Rec), F1-Score, AUC (Área sob a Curva ROC). | I11: Média de 94.0% de acurácia e 98.1% de precisão média em 17 modelos GAN, superando o método NPR (92.9%/96.4%). - Mais de 90% de acurácia na detecção de imagens criadas por 13 modelos de difusão diferentes. - ForenSynths: 94.2% Acc, 98.7% AP. - Self-Synthesis: 93.8% Acc, 97.5% AP. - Desempenho em modelos GAN específicos: ProGAN (99.9%/100.0%), StyleGAN (97.3%/99.9%), StyleGAN2 (95.5%/99.9%), BigGAN (92.7%/97.9%), RelGAN (100%/100%). - Desempenho em modelos de difusão específicos (treinado em DiFF I2I): Midjourney (99.9%/100.0%), SDXL (99.9%/100.0%), FreeDoM_T (99.8%/100.0%), HPS (99.2%/100.0%), SDXL Refiner (100.0%/100.0%), LoRA (99.9%/100.0%), DreamBooth (98.9%/100.0%), FreeDoM_I (99.8%/100.0%), DiffFace (96.8%/100.0%), DCFace (91.6%/99.7%), Imagic (99.8%/100.0%), CoDiff (99.7%/100.0%), CycleDiff (97.3%/99.8%). - FLOPs: 0.72B (significativamente menor que outros métodos). - Análise de Robustez Estatística: 93.6% (±0.5%) Acc e 98.1% (±0.4%) AP em diferentes seeds aleatórias. | J11: Desempenho ligeiramente inferior em CycleGAN e Deepfake em comparação com alguns métodos baseados em frequência. - Limitações com imagens contendo grandes regiões de céu, devido a inconsistências teóricas do prior de canal escuro nesses cenários. - Modelos treinados em condições de geração específicas (e.g., Face Swap) podem ter dificuldade em generalizar para outros tipos de imagens geradas. | K11: Melhorar a generalização de detectores de imagens geradas por IA para modelos não vistos. - Aumentar a interpretabilidade dos resultados de detecção para aplicações forenses. - Superar a dependência de artefatos de domínio de frequência específicos de modelos. - Lidar com a rápida evolução das tecnologias de geração de imagens. | L11: Otimização de estratégias de extração de características de canal escuro. - Desenvolvimento de mecanismos de ponderação adaptativos para melhorar o desempenho em cenários dominados pelo céu. - Exploração de aplicações na detecção de falsificações de vídeo. - Integração de informações de canal escuro com características RGB para detecção de imagens geradas. | M11: Combater a desinformação e fraude de identidade facilitadas por imagens geradas por IA. - Fornecer suporte técnico confiável para autenticação judicial, onde a interpretabilidade é crucial para a credibilidade das evidências. - Aumentar a confiança pública na autenticidade de imagens digitais. | N11: Detecção interpretável com prior de canal escuro: O uso do prior de canal escuro revela diferenças estatísticas sutis entre imagens reais e sintéticas que outros métodos ignoram. Ao combinar isso com bilinear pooling e convoluções 1x1, o DC-BiNet se destaca tanto em acurácia quanto em interpretabilidade, o que é especialmente relevante para aplicações forenses. A abordagem também é computacionalmente eficiente (0.72B FLOPs), tornando-a viável para uso em sistemas reais.Além disso, o modelo mantém consistência em diferentes seeds e cenários, evidenciando sua robustez estatística — algo raro em detectores baseados em redes profundas.
A12: 11 | B12: Deep Image Fingerprint: Towards Low Budget Synthetic Image Detection and Model Lineage Analysis | C12: Sinitsa, Sergey and Fried, Ohad | D12: 2024 | E12: Detecção interpretável de imagens geradas por IA, com foco em superar as limitações de generalização e interpretabilidade dos métodos existentes, utilizando o prior de canal escuro. | F12: Deep Image Fingerprint (DIF), Convolutional Neural Networks (CNNs), Generative Adversarial Networks (GANs), Diffusion Models, Large Text-to-Image Models (LTIMs), U-Net, DnCNN (denoising filter), Adam optimizer, Pearson Correlation Coefficient, Contrastive loss, resnet50, resnetM, Fast Fourier Transform (FFT). | G12: Stable Diffusion (SD 1.4, SD 2.1), MidJourney (MJ), DALL·E-Mini, GLIDE, DALL·E-2, CelebA-HQ, Places2, Laion-5B, AFHQ (para ProGANs), LSUN. | H12: Acurácia (ACC), Acurácia entre Detecções Cruzadas, Correlação Cruzada. | I12: DIF alcança alta acurácia de detecção com um número mínimo de amostras de treinamento (menos de 512 imagens), superando outros métodos treinados sob as mesmas condições e comparável a métodos SOTA pré-treinados em Stable Diffusion e MidJourney. Por exemplo, em SD 1.4, MJ e DALL·E-Mini, DIF alcança acurácias de 97.7% a 99.3% com 128 a 1024 amostras de treinamento. Em GANs, DIF alcança acurácias de 91.5% a 99.9% em diversos datasets. | J12: Alguns geradores de imagem produzem "impressões digitais" fracas, o que dificulta a detecção pelo DIF. O método tem desempenho insatisfatório em certos métodos de compressão e imagens borradas. O efeito da compressão na extração e detecção de "impressões digitais" requer investigação adicional. | K12: A necessidade de uma ferramenta automatizada para detectar imagens geradas por IA, dada a dificuldade de distinguir entre imagens reais e falsas. A proliferação de modelos de texto-para-imagem (LTIMs) e a necessidade de métodos de detecção que funcionem com poucos dados de treinamento. A detecção de imagens geradas por modelos "personalizados" (fine-tuned). A robustez dos métodos de detecção contra compressão de imagem. | L12: O uso de "impressões digitais" de CNNs para detecção de imagens geradas e análise de linhagem de modelos. A aplicação de cross-detection para rastrear modelos generativos fine-tuned. | M12: O uso malicioso de imagens geradas por IA com intenções enganosas, destacando a necessidade de ferramentas de detecção robustas para combater a desinformação. | N12: Detecção via Impressão Digital Espectral: O DIF explora artefatos gerados pelas estruturas de CNNs dos modelos sintéticos. Esses “fingerprints” são extraídos no domínio de frequência (FFT), oferecendo um método explicável e leve para detecção. Desempenho com Pouquíssimos Dados: Com apenas 128 a 1024 amostras, o DIF atinge até 99.3% de acurácia, provando eficácia mesmo com recursos limitados, ideal para aplicações práticas. Análise de Linhagem de Modelos: Além da detecção, o DIF permite traçar relações entre modelos fine-tuned, como identificar que imagens vieram de versões adaptadas de um mesmo modelo base (ex: SD 1.4 → DreamBooth). Limitações em Imagens com Compressão: Apesar do bom desempenho geral, o método perde precisão em imagens com artefatos fracos ou alta compressão, o que exige mais estudo sobre robustez espectral.
A13: 12 | B13: Deep learning model to detect deceptive generative adversarial network generated images using multimedia forensic | C13: Haewon Byeon and Mohammad Shabaz and Kapil Shrivastava and Anjali Joshi and Ismail Keshta and Rajvardhan Oak and Pavitar Parkash Singh and Mukesh Soni | D13: 2024 | E13: Detecção de imagens geradas por GANs (incluindo Deepfakes, adulteração de imagens e ocultação de informações) usando um modelo de Deep Learning que combina características de domínio espacial e de frequência para melhorar a precisão e a generalização. | F13: Rede Neural Convolucional (CNN) de fluxo duplo espacial-frequência, kernels de filtragem de domínio de frequência aprendíveis, rede de domínio de frequência, rede de domínio espacial, Transformada Cosseno Discreta (DCT), Transpose Convolution, Nearest-Neighbor Interpolation, LReLU (função de ativação), regularização L2, Softmax. | G13: StyleGAN, StyleGANII, PGGAN, WGAN, BEGAN, LSGAN (para imagens geradas por GANs), CelebA-HQ (para imagens reais). | H13: Acurácia (ACC). | I13: O modelo proposto alcançou a maior acurácia de classificação em todos os datasets de teste, confirmando sua eficácia na detecção de faces geradas por GAN. - O modelo combinado espacial-frequência alcançou mais de 99% de acurácia na detecção de StyleGAN. - O modelo alcançou 99.68% de acurácia na detecção de imagens com corte, mas teve desempenho reduzido sob outras perturbações (compressão, desfoque, ruído). | J13: O modelo tem resiliência limitada a ruído, compressão e desfoque, o que afeta a clareza dos artefatos de domínio de frequência. - Necessidade de otimização futura para minimizar os efeitos de ruído, compressão e desfoque. | K13: Aumento da qualidade e realismo das imagens geradas por GANs, tornando-as mais enganosas. - Ameaças à privacidade pessoal, ordem social e segurança nacional devido ao uso indevido de GANs. - Generalização de algoritmos de detecção para modelos GAN desconhecidos ou imagens com operações de edição. - Combinação eficaz de características de domínio espacial e de frequência. | L13: Aprimorar a robustez do modelo contra perturbações comuns de imagem. - Explorar técnicas para melhorar a adaptabilidade do modelo a diversas manipulações e variações de imagem. - Contribuir para a perícia multimídia e o combate à proliferação de deepfakes. | M13: Aumento da criação de conteúdo enganoso (Deepfakes, adulteração de imagens, ocultação de informações). - Violação da privacidade pessoal e perturbação da estabilidade social. - Necessidade de salvaguardar a autenticidade e integridade das imagens digitais. | N13: Fusão Espaço-Frequência Melhora a Detecção de Deepfakes A arquitetura dual-stream (espacial + frequência) com filtros aprendíveis mostrou desempenho excepcional (>99%) para GANs conhecidos, mas teve sua eficácia reduzida sob compressão e ruído. Isso revela o potencial da fusão de domínios, mas também a necessidade de maior robustez contra distorções comuns em ambientes reais.
A14: 13 | B14: Detection of AI-Generated Image Content in News and Journalism | C14: Jagadish, Tarun and Graceline Jasmine, S | D14: 2024 | E14: Este estudo tem como objetivo desenvolver e avaliar um modelo de aprendizado profundo altamente eficaz para detectar imagens geradas por IA em contextos de jornalismo e mídia. Diante da crescente ameaça representada por imagens sintéticas realistas criadas por modelos como GANs e modelos de difusão, os autores propõem uma abordagem baseada em CNN (Convolutional Neural Network) customizada, treinada em um conjunto de dados composto por imagens reais extraídas de sites jornalísticos e imagens falsas geradas com Stable Diffusion. O foco principal é proporcionar aos jornalistas uma ferramenta confiável para evitar a incorporação de conteúdo visual artificial em reportagens, com a finalidade de preservar a integridade jornalística e restaurar a confiança pública na mídia visual. | F14: Convolutional Neural Networks (CNN), InceptionV3 (Transfer Learning), ResNet50 (Transfer Learning), Neural Architecture Search (NAS), ReLU, MaxPooling, Dropout, Dense Layers, Sigmoid Activation, Softmax Activation, Data Augmentation, Early Stopping, Web Scraping, Stable Diffusion,StyleGAN, ProGAN, Diffusion Models (DMs) | G14: Imagens reais coletadas de sites jornalísticos (India Times, Times of India, Al Jazeera), imagens sintéticas geradas com Stable Diffusion, base final composta por 1.500 imagens reais e 1.200 imagens geradas por IA. | H14: Curvas de perda (Loss), Acurácia (ACC). | I14: O modelo CNN proposto atingiu 98.66% de acurácia no conjunto de treinamento e 98.15% no conjunto de validação ao final de 20 épocas, com perda final de 0.0420 (treino) e 0.0863 (validação). O modelo InceptionV3, usado como baseline de Transfer Learning, obteve 92.72% de acurácia de treino e 89.09% de validação. O ResNet50 apresentou desempenho inferior, alcançando apenas 82.90% no treino e 85.21% na validação. O CNN proposto demonstrou melhor eficiência de convergência, robustez na generalização e menor risco de overfitting, consolidando-se como superior às alternativas avaliadas. | J14: Apesar da performance elevada, os autores reconhecem que o modelo pode ser impactado por imagens de baixa qualidade, ataques adversariais e a diversidade de técnicas gerativas. A ausência de testes com outros modelos generativos além do Stable Diffusion também é uma limitação metodológica, assim como a ausência de avaliação cruzada com bases abertas e padronizadas internacionalmente. Além disso, o número relativamente baixo de imagens sintéticas (1.200) pode limitar a capacidade de generalização diante de variações não contempladas durante o treinamento. | K14: Os principais desafios enfrentados incluem: a crescente sofisticação de imagens geradas por IA; a dificuldade de distinguir padrões artificiais sutis de aspectos visuais naturais; a necessidade de ferramentas eficazes e acessíveis para contextos jornalísticos; e a vulnerabilidade dos sistemas de detecção a ataques adversariais. O estudo também reconhece o desafio técnico de manter a eficácia de detecção frente à rápida evolução dos modelos generativos. | L14: Arquitetura CNN customizada otimizada por NAS, uso de camadas convolucionais com ativação ReLU e pooling max, integração de múltiplas camadas Dense com Dropout, Transfer Learning com InceptionV3 e ResNet50 para fins comparativos, uso de geração sintética via Stable Diffusion para composição do dataset, Web Scraping automatizado para coleta de dados reais de veículos jornalísticos. | M14: O artigo enfatiza que a disseminação de imagens falsas compromete a confiança pública na mídia e prejudica a integridade jornalística. Em um cenário onde imagens são usadas como evidência de fatos, a incapacidade de distinguir entre o real e o artificial pode permitir a propagação de desinformação e manipulação de narrativas. Ferramentas de detecção robustas são vistas como essenciais para conter o uso malicioso da IA na produção de conteúdo visual. O trabalho reconhece que o avanço técnico precisa ser acompanhado por diretrizes éticas e regulatórias voltadas à transparência e verificação da veracidade visual. | N14: O artigo propõe uma abordagem eficaz e leve para detecção de imagens geradas por IA, centrada em uma arquitetura CNN que supera modelos de Transfer Learning como InceptionV3 e ResNet50 tanto em acurácia quanto em velocidade de convergência. Utilizando uma base mista composta por imagens reais de sites jornalísticos e imagens falsas geradas com Stable Diffusion, o modelo atinge desempenho notável e boa capacidade de generalização. A proposta se destaca por seu potencial de aplicação direta em ambientes jornalísticos e sua viabilidade computacional. Além disso, os autores destacam que, frente à intensificação do uso de imagens falsas como instrumento de desinformação, soluções como esta são urgentes para garantir a integridade da mídia visual. O estudo contribui significativamente para o campo da detecção forense de imagens, propondo uma alternativa técnica eficaz e viável para contextos do mundo real.
A15: 14 | B15: Detection of GAN generated image using color gradient representation | C15: Yun Liu and Zuliang Wan and Xiaohua Yin and Guanghui Yue and Aiping Tan and Zhi Zheng | D15: 2023 | E15: Detecção de imagens geradas por GANs usando análise de gradiente de cor. | F15: Análise de gradiente de cor, Gradient-domain Local Dirctional Number (GLDN), Multi-GLDN histogram (MGLH), classificador Ensemble,High-Pass Filters ( Sobel), DCT (mencionado como uma técnica para transformar imagens para o domínio da frequência em outros trabalhos, mas o foco aqui é no gradiente de cor). | G15: PGGAN, StyleGAN2, CelebA HQ, CelebA, StyleGAN, CycleGAN, BigGAN, GauGAN, StarGAN. | H15: Acurácia (ACC), Revocação (rec), Precisão(P), AUC. | I15: Acurácia de 99.4% no dataset PGGAN (melhor que outros métodos). - Acurácia de 99.8% no dataset StyleGAN2 (melhor que outros métodos). - Desempenho estável e alto (acima de 96%) em StyleGAN, BigGAN, CycleGAN, StarGAN, GauGAN. - Melhor desempenho em compressão e redimensionamento. | J15: Desempenho ligeiramente inferior em filtragem de mediana. - O vetor de características final tem uma dimensão mais longa devido à extração de características em blocos de imagem. | K15: Dificuldade para humanos distinguirem imagens geradas por GANs. - Riscos sociais, morais, legais e de segurança devido ao uso indevido de imagens geradas por GANs (notícias falsas, fraude). - Generalização e robustez dos métodos de detecção. - Interpretabilidade dos modelos de Deep Learning. | L15: Explorar a informação de cor e gradiente como pistas para detecção de imagens GAN. - Utilizar histogramas Multi-GLDN para quantificar informações de textura de gradiente. - Desenvolver métodos mais gerais para detectar imagens falsas geradas por diferentes GANs. | M15: Potencial ameaça à sociedade devido à capacidade de GANs gerarem falsificações para enganar humanos. - Necessidade de estabelecer um forte mecanismo de defesa para evitar os riscos da inteligência artificial. | N15: Gradientes de Cor São Indicadores Visuais Potentes A análise de gradientes em múltiplos espaços de cor, combinada com histogramas direcionais (MGLH), alcançou altos índices de acurácia (>99%) para diversos GANs. Além da precisão, a abordagem destaca-se pela interpretabilidade, mas sofre com aumento da dimensionalidade do vetor de características e leve queda sob filtragem de mediana.
